Workbook

Sheet 填寫說明
A1: 高雄市楠梓國小 115 學年度 排課需求收集表
A2: 用途：收集排課所需資料，填好後直接匯入排課系統。系統只排科任課，排完後剩下的節次由導師自己排。
A4: 頁 | B4: 工作表 | C4: 填什麼 | D4: 誰來填
A5: 1 | B5: 規則表 | C5: 全部排課規則，一列一條。要新增規則就加一列；暫停就把「啟用」改成「否」 | D5: 教學組長
A6: 2 | B6: 科任配課 | C6: 哪位科任老師教哪一班、什麼科目、每週幾節、在哪裡上 | D6: 教學組長
A7: 3 | B7: 本土語預排 | C7: 學校已排好的本土語時段（系統直接鎖定） | D7: 本土語承辦人
A8: 4 | B8: 特教抽離 | C8: 抽離／集中式特教的班級、節次、抽離科目（不填學生姓名） | D8: 特教承辦人
A9: 5 | B9: 共同時段 | C9: 學校共同課、年段共同時段、綠色迪士尼、低年級下午不上課 | D9: 教學組長
A10: 6 | B10: 職務限制 | C10: 教育局規定的職務不排時段＋擔任這些職務的老師名單（最優先處理） | D10: 教學組長／人事
A11: 7 | B11: 班級教室 | C11: 每班教室位置（計算跑班距離）與專科教室間數 | D11: 教學組長／總務
A12: 8 | B12: 老師需求 | C12: 老師不想被排的時段與特殊要求 | D12: 教學組長彙整
A13: 9 | B13: 老師需求單 | C13: 列印發給老師填寫的紙本（灰階，一人一張） | D13: 科任老師
A14: 10 | B14: 節數檢核 | C14: 自動計算，不用填：每班科任節數、本土語節數 | D14: —
A16: 填寫方式
B17: 淺灰底格子 | C17: 請填寫（多數欄位有下拉選單，點格子右邊的小箭頭選）
B18: 斜體灰字列 | C18: 範例，看完可以刪除，或直接覆蓋
B19: 深灰底格子 | C19: 已鎖定的內容（不用改）
A21: 老師需求的填寫原則
A22: ・每位老師「必須」最多 3 節（職務規定的不排時段另計，不佔名額），其餘請勾「希望」
A23: ・「必須」＝絕對不能排；「希望」＝盡量不排，但必要時可能會排
A24: ・第七節不排正課（國、數、英、社、自）；第七節可排體育、音樂、美勞、綜合、彈性
A25: ・大下課、午休算休息；科任每天盡量 6 節以下
A27: 填寫期限：＿＿＿＿年＿＿月＿＿日 承辦：教學組

Sheet 規則表
A1: 1. 規則表（一列一條規則）
A2: 層級：0 法規＝教育局／教育部規定，最優先、不能違反；1 鎖定＝先鎖住不動；2 必須＝不能違反；3 盡量＝盡量做到（重要度高／中／低）。要新增規則就往下加一列；暫停規則把「啟用」改成「否」。「原因」欄給下一任承辦人看。
A3: 編號 | B3: 層級 | C3: 規則積木 | D3: 對象 | E3: 內容 | F3: 重要度 | G3: 啟用 | H3: 原因
A4: R01 | B4: 0 法規 | C4: 職務不排時段 | D4: 依職務 | E4: 擔任特定職務的老師不排指定時段（依「職務限制」頁） | F4: — | G4: 是 | H4: 教育局規定
A5: R02 | B5: 0 法規 | C5: 科目不排時段 | D5: 國、數、英、社、自 | E5: 不排第7節 | F5: — | G5: 是 | H5: 教育部規定
A6: R03 | B6: 1 鎖定 | C6: 鎖定時段 | D6: 本土語 | E6: 依「本土語預排」頁 | F6: — | G6: 是 | H6: 學校預先排好
A7: R04 | B7: 1 鎖定 | C7: 鎖定時段 | D7: 特教抽離 | E7: 依「特教抽離」頁；原班該節由導師上被抽的科目 | F7: — | G7: 是 | H7: 學生抽離時原班要上同科目
A8: R05 | B8: 1 鎖定 | C8: 鎖定時段 | D8: 三、四年級 | E8: 星期一 第5–7節 綜合（導師上） | F8: — | G8: 是 | H8: 年段共同時段
A9: R06 | B9: 1 鎖定 | C9: 鎖定時段 | D9: 五、六年級 | E9: 星期四 第5–7節 綜合（導師上） | F9: — | G9: 是 | H9: 年段共同時段
A10: R07 | B10: 1 鎖定 | C10: 鎖定時段 | D10: 全校 | E10: 星期三 第1節 綠色迪士尼（導師上） | F10: — | G10: 是 | H10: 學校共同時段
A11: R08 | B11: 1 鎖定 | C11: 鎖定時段 | D11: 一、二年級 | E11: 下午不上課的日子（依「共同時段」頁） | F11: — | G11: 是 | H11: 沿用目前作息
A12: R09 | B12: 2 必須 | C12: 其他 | D12: 所有老師 | E12: 同一位老師同一節只能在一個班 | F12: — | G12: 是 | H12: 基本規則
A13: R10 | B13: 2 必須 | C13: 教室容量 | D13: 專科教室 | E13: 同一節使用班數不超過教室間數（電腦教室 2 間） | F13: — | G13: 是 | H13: 避免教室重複
A14: R11 | B14: 2 必須 | C14: 連堂 | D14: 自然 | E14: 每班每週3節：2節連堂在自然教室（可跨大下課）＋1節在原班，原班那節排不同天 | F14: — | G14: 是 | H14: 實驗需要連堂
... A21: R18 | B21: 3 盡量 | C21: 間隔天數 | D21: 自然 | E21: 同一班自然各次上課至少隔 1 天（例：星期一上連堂，原班那節排星期三以後） | F21: 中 | G21: 是 | H21: Bing 2026-10-21：原班那節要不同天，最好差一天

Sheet 科任配課
A1: 2. 科任配課
A2: 一列＝一位老師在一個班上一個科目。同一位老師教很多班就填很多列。「此老師每週總節數」會自動算（每天 6 節以下＝每週最多 30 節）。
A3: 教師姓名 | B3: 科目 | C3: 班級 | D3: 每週節數 | E3: 上課地點 | F3: 連堂節數 | G3: 備註 | H3: 此老師每週總節數
A4: （範例）王小明 | B4: 自然 | C4: 3年1班 | D4: 3 | E4: 自然教室 | F4: 2 | G4: 另1節在原班
A5: 英語甲 | B5: 英語 | C5: 1年1班 | D5: 1 | E5: 原班教室 | H5: =IF(A5="","",SUMIF($A$5:$A$304,A5,$D$5:$D$304))
A6: 英語甲 | B6: 英語 | C6: 1年2班 | D6: 1 | E6: 原班教室 | H6: =IF(A6="","",SUMIF($A$5:$A$304,A6,$D$5:$D$304))
A7: 英語甲 | B7: 英語 | C7: 1年3班 | D7: 1 | E7: 原班教室 | H7: =IF(A7="","",SUMIF($A$5:$A$304,A7,$D$5:$D$304))
A8: 英語甲 | B8: 英語 | C8: 1年4班 | D8: 1 | E8: 原班教室 | H8: =IF(A8="","",SUMIF($A$5:$A$304,A8,$D$5:$D$304))
A9: 英語甲 | B9: 英語 | C9: 1年5班 | D9: 1 | E9: 原班教室 | H9: =IF(A9="","",SUMIF($A$5:$A$304,A9,$D$5:$D$304))
A10: 英語甲 | B10: 英語 | C10: 1年6班 | D10: 1 | E10: 原班教室 | H10: =IF(A10="","",SUMIF($A$5:$A$304,A10,$D$5:$D$304))
A11: 英語甲 | B11: 英語 | C11: 1年7班 | D11: 1 | E11: 原班教室 | H11: =IF(A11="","",SUMIF($A$5:$A$304,A11,$D$5:$D$304))
A12: 英語甲 | B12: 英語 | C12: 1年8班 | D12: 1 | E12: 原班教室 | H12: =IF(A12="","",SUMIF($A$5:$A$304,A12,$D$5:$D$304))
A13: 英語甲 | B13: 英語 | C13: 1年9班 | D13: 1 | E13: 原班教室 | H13: =IF(A13="","",SUMIF($A$5:$A$304,A13,$D$5:$D$304))
A14: 英語甲 | B14: 英語 | C14: 1年10班 | D14: 1 | E14: 原班教室 | H14: =IF(A14="","",SUMIF($A$5:$A$304,A14,$D$5:$D$304))
A15: 英語甲 | B15: 英語 | C15: 1年11班 | D15: 1 | E15: 原班教室 | H15: =IF(A15="","",SUMIF($A$5:$A$304,A15,$D$5:$D$304))
A16: 英語甲 | B16: 英語 | C16: 1年12班 | D16: 1 | E16: 原班教室 | H16: =IF(A16="","",SUMIF($A$5:$A$304,A16,$D$5:$D$304))
... A217: 音樂己 | B217: 音樂 | C217: 6年12班 | D217: 2 | E217: 音樂教室 | H217: =IF(A217="","",SUMIF($A$5:$A$304,A217,$D$5:$D$304))
A218: 自然甲 | B218: 自然 | C218: 3年1班 | D218: 3 | E218: 自然教室 | F218: 2 | G218: 另1節在原班 | H218: =IF(A218="","",SUMIF($A$5:$A$304,A218,$D$5:$D$304))
A219: 自然甲 | B219: 自然 | C219: 3年2班 | D219: 3 | E219: 自然教室 | F219: 2 | G219: 另1節在原班 | H219: =IF(A219="","",SUMIF($A$5:$A$304,A219,$D$5:$D$304))
A220: 自然甲 | B220: 自然 | C220: 3年3班 | D220: 3 | E220: 自然教室 | F220: 2 | G220: 另1節在原班 | H220: =IF(A220="","",SUMIF($A$5:$A$304,A220,$D$5:$D$304))
A221: 自然甲 | B221: 自然 | C221: 3年4班 | D221: 3 | E221: 自然教室 | F221: 2 | G221: 另1節在原班 | H221: =IF(A221="","",SUMIF($A$5:$A$304,A221,$D$5:$D$304))
A222: 自然甲 | B222: 自然 | C222: 3年5班 | D222: 3 | E222: 自然教室 | F222: 2 | G222: 另1節在原班 | H222: =IF(A222="","",SUMIF($A$5:$A$304,A222,$D$5:$D$304))
A223: 自然甲 | B223: 自然 | C223: 3年6班 | D223: 3 | E223: 自然教室 | F223: 2 | G223: 另1節在原班 | H223: =IF(A223="","",SUMIF($A$5:$A$304,A223,$D$5:$D$304))
A224: 自然甲 | B224: 自然 | C224: 3年7班 | D224: 3 | E224: 自然教室 | F224: 2 | G224: 另1節在原班 | H224: =IF(A224="","",SUMIF($A$5:$A$304,A224,$D$5:$D$304))
A225: 自然乙 | B225: 自然 | C225: 3年8班 | D225: 3 | E225: 自然教室 | F225: 2 | G225: 另1節在原班 | H225: =IF(A225="","",SUMIF($A$5:$A$304,A225,$D$5:$D$304))
A226: 自然乙 | B226: 自然 | C226: 3年9班 | D226: 3 | E226: 自然教室 | F226: 2 | G226: 另1節在原班 | H226: =IF(A226="","",SUMIF($A$5:$A$304,A226,$D$5:$D$304))
A227: 自然乙 | B227: 自然 | C227: 3年10班 | D227: 3 | E227: 自然教室 | F227: 2 | G227: 另1節在原班 | H227: =IF(A227="","",SUMIF($A$5:$A$304,A227,$D$5:$D$304))
A228: 自然乙 | B228: 自然 | C228: 3年11班 | D228: 3 | E228: 自然教室 | F228: 2 | G228: 另1節在原班 | H228: =IF(A228="","",SUMIF($A$5:$A$304,A228,$D$5:$D$304))
A229: 自然乙 | B229: 自然 | C229: 3年12班 | D229: 3 | E229: 自然教室 | F229: 2 | G229: 另1節在原班 | H229: =IF(A229="","",SUMIF($A$5:$A$304,A229,$D$5:$D$304))
... A265: 自然庚 | B265: 自然 | C265: 6年12班 | D265: 3 | E265: 自然教室 | F265: 2 | G265: 另1節在原班 | H265: =IF(A265="","",SUMIF($A$5:$A$304,A265,$D$5:$D$304))
A266: 資訊甲 | B266: 資訊 | C266: 3年1班 | D266: 1 | E266: 電腦教室 | H266: =IF(A266="","",SUMIF($A$5:$A$304,A266,$D$5:$D$304))
A267: 資訊甲 | B267: 資訊 | C267: 3年2班 | D267: 1 | E267: 電腦教室 | H267: =IF(A267="","",SUMIF($A$5:$A$304,A267,$D$5:$D$304))
A268: 資訊甲 | B268: 資訊 | C268: 3年3班 | D268: 1 | E268: 電腦教室 | H268: =IF(A268="","",SUMIF($A$5:$A$304,A268,$D$5:$D$304))
A269: 資訊甲 | B269: 資訊 | C269: 3年4班 | D269: 1 | E269: 電腦教室 | H269: =IF(A269="","",SUMIF($A$5:$A$304,A269,$D$5:$D$304))
A270: 資訊甲 | B270: 資訊 | C270: 3年5班 | D270: 1 | E270: 電腦教室 | H270: =IF(A270="","",SUMIF($A$5:$A$304,A270,$D$5:$D$304))
A271: 資訊甲 | B271: 資訊 | C271: 3年6班 | D271: 1 | E271: 電腦教室 | H271: =IF(A271="","",SUMIF($A$5:$A$304,A271,$D$5:$D$304))
A272: 資訊甲 | B272: 資訊 | C272: 3年7班 | D272: 1 | E272: 電腦教室 | H272: =IF(A272="","",SUMIF($A$5:$A$304,A272,$D$5:$D$304))
A273: 資訊甲 | B273: 資訊 | C273: 3年8班 | D273: 1 | E273: 電腦教室 | H273: =IF(A273="","",SUMIF($A$5:$A$304,A273,$D$5:$D$304))
A274: 資訊甲 | B274: 資訊 | C274: 3年9班 | D274: 1 | E274: 電腦教室 | H274: =IF(A274="","",SUMIF($A$5:$A$304,A274,$D$5:$D$304))
A275: 資訊甲 | B275: 資訊 | C275: 3年10班 | D275: 1 | E275: 電腦教室 | H275: =IF(A275="","",SUMIF($A$5:$A$304,A275,$D$5:$D$304))
...

Sheet 本土語預排
A1: 3. 本土語預排
A2: 學校已排好的本土語時段，系統會直接鎖定。一列＝一班的一個時段。跨班分組上課時，每個參與的班級都要各填一列。
A3: 班級 | B3: 星期 | C3: 節次 | D3: 語別 | E3: 授課教師 | F3: 上課地點 | G3: 備註
A4: 3年1班 | B4: 二 | C4: 3 | D4: 閩南語 | E4: （範例）陳老師 | F4: 原班教室
A5: 6年3班 | B5: 三 | C5: 3 | D5: 閩南語 | E5: 閩南語甲 | F5: 原班教室
A6: 3年7班 | B6: 五 | C6: 2 | D6: 閩南語 | E6: 閩南語甲 | F6: 原班教室
A7: 4年5班 | B7: 二 | C7: 5 | D7: 閩南語 | E7: 閩南語甲 | F7: 原班教室
A8: 1年2班 | B8: 一 | C8: 1 | D8: 閩南語 | E8: 閩南語甲 | F8: 原班教室
A9: 5年9班 | B9: 一 | C9: 3 | D9: 閩南語 | E9: 閩南語甲 | F9: 原班教室
A10: 6年11班 | B10: 二 | C10: 1 | D10: 閩南語 | E10: 閩南語甲 | F10: 原班教室
A11: 1年8班 | B11: 一 | C11: 2 | D11: 閩南語 | E11: 閩南語甲 | F11: 原班教室
A12: 1年5班 | B12: 四 | C12: 2 | D12: 閩南語 | E12: 閩南語甲 | F12: 原班教室
A13: 6年5班 | B13: 四 | C13: 1 | D13: 閩南語 | E13: 閩南語甲 | F13: 原班教室
A14: 3年2班 | B14: 五 | C14: 4 | D14: 閩南語 | E14: 閩南語甲 | F14: 原班教室
A15: 3年10班 | B15: 五 | C15: 1 | D15: 閩南語 | E15: 閩南語甲 | F15: 原班教室
... A73: 2年3班 | B73: 五 | C73: 3 | D73: 閩南語 | E73: 閩南語丁 | F73: 原班教室
A74: 3年3班 | B74: 一 | C74: 4 | D74: 閩南語 | E74: 英語乙 | F74: 原班教室 | G74: （試跑）科任兼本土語
A75: 4年2班 | B75: 一 | C75: 1 | D75: 閩南語 | E75: 英語乙 | F75: 原班教室 | G75: （試跑）科任兼本土語
A76: 4年6班 | B76: 二 | C76: 1 | D76: 客語 | E76: 客語甲 | F76: 本土語教室 | G76: 分組上課
A77: 3年7班 | B77: 五 | C77: 2 | D77: 族語 | E77: 族語甲 | F77: 本土語教室 | G77: 分組上課
A78: 6年7班 | B78: 五 | C78: 3 | D78: 客語 | E78: 客語甲 | F78: 本土語教室 | G78: 分組上課
A79: 5年10班 | B79: 二 | C79: 6 | D79: 客語 | E79: 客語甲 | F79: 本土語教室 | G79: 分組上課
A80: 4年12班 | B80: 二 | C80: 3 | D80: 族語 | E80: 族語甲 | F80: 本土語教室 | G80: 分組上課
A81: 3年6班 | B81: 四 | C81: 4 | D81: 族語 | E81: 族語甲 | F81: 本土語教室 | G81: 分組上課
A82: 4年7班 | B82: 三 | C82: 3 | D82: 新住民語 | E82: 新住民語甲 | F82: 本土語教室 | G82: 分組上課
A83: 3年11班 | B83: 四 | C83: 3 | D83: 族語 | E83: 族語甲 | F83: 本土語教室 | G83: 分組上課
A84: 1年10班 | B84: 四 | C84: 2 | D84: 新住民語 | E84: 新住民語甲 | F84: 本土語教室 | G84: 分組上課
A85: 1年6班 | B85: 二 | C85: 3 | D85: 客語 | E85: 客語甲 | F85: 本土語教室 | G85: 分組上課

Sheet 特教抽離
A1: 4. 特教抽離
A2: 請勿填寫學生姓名。抽離時段原班要上「抽離科目」（由導師上），系統會把那一節保留給導師並標示科目。
A3: 類型 | B3: 原班級 | C3: 抽離科目 | D3: 星期 | E3: 節次 | F3: 特教老師 | G3: 抽離人數 | H3: 備註
A4: 資源班抽離 | B4: 4年2班 | C4: 數學 | D4: 一 | E4: 2 | F4: （範例）林老師 | G4: 2 | H4: 同時段另有4年5班
A5: 資源班抽離 | B5: 6年12班 | C5: 數學 | D5: 二 | E5: 4 | F5: 資源班甲 | G5: 2
A6: 資源班抽離 | B6: 2年1班 | C6: 國語 | D6: 三 | E6: 4 | F6: 資源班乙 | G6: 2
A7: 資源班抽離 | B7: 3年1班 | C7: 國語 | D7: 三 | E7: 3 | F7: 資源班丙 | G7: 2
A8: 資源班抽離 | B8: 5年6班 | C8: 數學 | D8: 四 | E8: 2 | F8: 資源班甲 | G8: 1
A9: 資源班抽離 | B9: 4年8班 | C9: 國語 | D9: 三 | E9: 3 | F9: 資源班乙 | G9: 2
A10: 資源班抽離 | B10: 3年2班 | C10: 數學 | D10: 二 | E10: 1 | F10: 資源班丙 | G10: 3
A11: 資源班抽離 | B11: 6年3班 | C11: 數學 | D11: 四 | E11: 2 | F11: 資源班甲 | G11: 2
A12: 資源班抽離 | B12: 5年8班 | C12: 數學 | D12: 二 | E12: 4 | F12: 資源班乙 | G12: 1
A13: 資源班抽離 | B13: 4年11班 | C13: 數學 | D13: 二 | E13: 3 | F13: 資源班丙 | G13: 2
A14: 資源班抽離 | B14: 4年7班 | C14: 國語 | D14: 五 | E14: 1 | F14: 資源班甲 | G14: 2

Sheet 共同時段
A1: 5. 共同時段
A2: 學校共同課、年段共同時段等全部要先鎖住的時段。已填好目前確認的內容，請補上空白處。
A3: 對象 | B3: 星期 | C3: 節次 | D3: 課程／活動 | E3: 誰上 | F3: 鎖定 | G3: 備註
A4: 全校 | B4: 三 | C4: 1 | D4: 綠色迪士尼 | E4: 導師 | F4: 是
A5: 三、四年級 | B5: 一 | C5: 5–7 | D5: 綜合 | E5: 導師 | F5: 是 | G5: 年段共同時段
A6: 五、六年級 | B6: 四 | C6: 5–7 | D6: 綜合 | E6: 導師 | F6: 是 | G6: 年段共同時段
A7: 全校 | B7: 三 | C7: 下午 | D7: 不上課 | E7: — | F7: 是 | G7: （試跑假設）星期三下午全校不上課
A8: 一、二年級 | B8: 一 | C8: 下午 | D8: 不上課 | E8: — | F8: 是 | G8: （試跑假設）低年級只有星期二整天
A9: 一、二年級 | B9: 三 | C9: 下午 | D9: 不上課 | E9: — | F9: 是 | G9: （試跑假設）低年級只有星期二整天
A10: 一、二年級 | B10: 四 | C10: 下午 | D10: 不上課 | E10: — | F10: 是 | G10: （試跑假設）低年級只有星期二整天
A11: 一、二年級 | B11: 五 | C11: 下午 | D11: 不上課 | E11: — | F11: 是 | G11: （試跑假設）低年級只有星期二整天

Sheet 職務限制
A1: 6. 職務限制（教育局規定，最優先）
A2: 左邊：規則跟著「職務」走，不跟著人。明年只要更新右邊的名單，規則不用重填。請在「依據」欄寫上公文文號或規定名稱，方便交接查證。
A3: 職務 | B3: 星期 | C3: 節次／時段 | D3: 依據（文號／規定） | E3: 備註 | G3: 教師姓名 | H3: 擔任職務
A4: （試跑）英語輔導團團員 | B4: 四 | C4: 上午 | D4: 高市教○字第000001號（假） | G4: 英語丙 | H4: （試跑）英語輔導團團員
A5: （試跑）自然輔導團團員 | B5: 二 | C5: 下午 | D5: 高市教○字第000002號（假） | G5: 自然丁 | H5: （試跑）自然輔導團團員

Sheet 班級教室
A1: 7. 班級教室位置
A2: 用來計算跑班距離：同一位老師連續兩節，盡量排在同棟、同層或相鄰的教室。右邊是專科教室清單。
A3: 班級 | B3: 棟別 | C3: 樓層 | D3: 教室編號 | E3: 備註 | G3: 專科教室 | H3: 間數 | I3: 同一節最多幾班 | J3: 位置（棟／樓） | K3: 使用科目
A4: 1年1班 | B4: 甲棟 | C4: 1 | D4: 甲101 | G4: 自然教室 | H4: 4 | I4: 4 | J4: 丁棟2-3F | K4: 自然
A5: 1年2班 | B5: 甲棟 | C5: 1 | D5: 甲102 | G5: 音樂教室 | H5: 5 | I5: 5 | J5: 丁棟1F | K5: 音樂
A6: 1年3班 | B6: 甲棟 | C6: 1 | D6: 甲103 | G6: 電腦教室 | H6: 2 | I6: 2 | J6: 丁棟4F | K6: 資訊
A7: 1年4班 | B7: 甲棟 | C7: 1 | D7: 甲104 | G7: 操場／體育館 | H7: 1 | I7: 8 | J7: 操場 | K7: 體育
A8: 1年5班 | B8: 甲棟 | C8: 1 | D8: 甲105
A9: 1年6班 | B9: 甲棟 | C9: 1 | D9: 甲106
A10: 1年7班 | B10: 甲棟 | C10: 2 | D10: 甲201
A11: 1年8班 | B11: 甲棟 | C11: 2 | D11: 甲202
A12: 1年9班 | B12: 甲棟 | C12: 2 | D12: 甲203
A13: 1年10班 | B13: 甲棟 | C13: 2 | D13: 甲204
A14: 1年11班 | B14: 甲棟 | C14: 2 | D14: 甲205
A15: 1年12班 | B15: 甲棟 | C15: 2 | D15: 甲206
A16: 2年1班 | B16: 乙棟 | C16: 1 | D16: 乙101
A17: 2年2班 | B17: 乙棟 | C17: 1 | D17: 乙102
A18: 2年3班 | B18: 乙棟 | C18: 1 | D18: 乙103
A19: 2年4班 | B19: 乙棟 | C19: 1 | D19: 乙104
... A74: 6年12班 | B74: 丙棟 | C74: 4 | D74: 丙406

Sheet 老師需求
A1: 8. 老師個人需求
A2: 一列＝一個不想被排的時段。「必須」每人最多 3 節，其餘請選「希望」。節次可選 1–7，或上午／下午／整天。
A3: 教師姓名 | B3: 星期 | C3: 節次／時段 | D3: 程度 | E3: 原因（選填） | F3: 此老師「必須」節數
A4: （範例）王小明 | B4: 五 | C4: 下午 | D4: 希望 | E4: 接送小孩
A5: 音樂己 | B5: 五 | C5: 1 | D5: 希望 | F5: =IF(A5="","",COUNTIFS($A$5:$A$304,A5,$D$5:$D$304,"必須"))
A6: 體育丁 | B6: 一 | C6: 6 | D6: 必須 | E6: 身體因素 | F6: =IF(A6="","",COUNTIFS($A$5:$A$304,A6,$D$5:$D$304,"必須"))
A7: 體育丁 | B7: 五 | C7: 3 | D7: 必須 | F7: =IF(A7="","",COUNTIFS($A$5:$A$304,A7,$D$5:$D$304,"必須"))
A8: 體育丁 | B8: 一 | C8: 1 | D8: 希望 | F8: =IF(A8="","",COUNTIFS($A$5:$A$304,A8,$D$5:$D$304,"必須"))
A9: 健康丙 | B9: 五 | C9: 下午 | D9: 希望 | E9: 接送小孩 | F9: =IF(A9="","",COUNTIFS($A$5:$A$304,A9,$D$5:$D$304,"必須"))
A10: 社會丙 | B10: 五 | C10: 1 | D10: 必須 | E10: 身體因素 | F10: =IF(A10="","",COUNTIFS($A$5:$A$304,A10,$D$5:$D$304,"必須"))
A11: 社會丙 | B11: 五 | C11: 6 | D11: 必須 | E11: 身體因素 | F11: =IF(A11="","",COUNTIFS($A$5:$A$304,A11,$D$5:$D$304,"必須"))
A12: 社會丙 | B12: 三 | C12: 1 | D12: 希望 | F12: =IF(A12="","",COUNTIFS($A$5:$A$304,A12,$D$5:$D$304,"必須"))
A13: 資訊甲 | B13: 五 | C13: 下午 | D13: 希望 | E13: 接送小孩 | F13: =IF(A13="","",COUNTIFS($A$5:$A$304,A13,$D$5:$D$304,"必須"))
A14: 健康甲 | B14: 五 | C14: 2 | D14: 必須 | F14: =IF(A14="","",COUNTIFS($A$5:$A$304,A14,$D$5:$D$304,"必須"))
A15: 健康甲 | B15: 三 | C15: 6 | D15: 必須 | E15: 身體因素 | F15: =IF(A15="","",COUNTIFS($A$5:$A$304,A15,$D$5:$D$304,"必須"))
A16: 健康甲 | B16: 五 | C16: 下午 | D16: 希望 | E16: 接送小孩 | F16: =IF(A16="","",COUNTIFS($A$5:$A$304,A16,$D$5:$D$304,"必須"))
A17: 英語丁 | B17: 五 | C17: 6 | D17: 必須 | E17: 進修 | F17: =IF(A17="","",COUNTIFS($A$5:$A$304,A17,$D$5:$D$304,"必須"))
A18: 英語丁 | B18: 一 | C18: 4 | D18: 必須 | E18: 兼任行政會議 | F18: =IF(A18="","",COUNTIFS($A$5:$A$304,A18,$D$5:$D$304,"必須"))
A19: 英語丁 | B19: 二 | C19: 4 | D19: 必須 | E19: 身體因素 | F19: =IF(A19="","",COUNTIFS($A$5:$A$304,A19,$D$5:$D$304,"必須"))
A20: 英語丁 | B20: 五 | C20: 下午 | D20: 希望 | E20: 接送小孩 | F20: =IF(A20="","",COUNTIFS($A$5:$A$304,A20,$D$5:$D$304,"必須"))
A21: 自然丙 | B21: 五 | C21: 2 | D21: 必須 | F21: =IF(A21="","",COUNTIFS($A$5:$A$304,A21,$D$5:$D$304,"必須"))
A22: 自然丙 | B22: 五 | C22: 下午 | D22: 希望 | E22: 接送小孩 | F22: =IF(A22="","",COUNTIFS($A$5:$A$304,A22,$D$5:$D$304,"必須"))
A23: 音樂丁 | B23: 四 | C23: 3 | D23: 必須 | E23: 接送小孩 | F23: =IF(A23="","",COUNTIFS($A$5:$A$304,A23,$D$5:$D$304,"必須"))
A24: 音樂丁 | B24: 三 | C24: 6 | D24: 必須 | E24: 接送小孩 | F24: =IF(A24="","",COUNTIFS($A$5:$A$304,A24,$D$5:$D$304,"必須"))
A25: 音樂丁 | B25: 二 | C25: 2 | D25: 必須 | E25: 接送小孩 | F25: =IF(A25="","",COUNTIFS($A$5:$A$304,A25,$D$5:$D$304,"必須"))
A26: 音樂丁 | B26: 五 | C26: 下午 | D26: 希望 | E26: 接送小孩 | F26: =IF(A26="","",COUNTIFS($A$5:$A$304,A26,$D$5:$D$304,"必須"))
A27: 社會丁 | B27: 五 | C27: 下午 | D27: 希望 | E27: 接送小孩 | F27: =IF(A27="","",COUNTIFS($A$5:$A$304,A27,$D$5:$D$304,"必須"))
A28: 自然乙 | B28: 四 | C28: 3 | D28: 必須 | E28: 接送小孩 | F28: =IF(A28="","",COUNTIFS($A$5:$A$304,A28,$D$5:$D$304,"必須"))
A29: 自然乙 | B29: 四 | C29: 1 | D29: 希望 | F29: =IF(A29="","",COUNTIFS($A$5:$A$304,A29,$D$5:$D$304,"必須"))
F30: =IF(A30="","",COUNTIFS($A$5:$A$304,A30,$D$5:$D$304,"必須"))
F31: =IF(A31="","",COUNTIFS($A$5:$A$304,A31,$D$5:$D$304,"必須"))
F32: =IF(A32="","",COUNTIFS($A$5:$A$304,A32,$D$5:$D$304,"必須"))
F33: =IF(A33="","",COUNTIFS($A$5:$A$304,A33,$D$5:$D$304,"必須"))
F34: =IF(A34="","",COUNTIFS($A$5:$A$304,A34,$D$5:$D$304,"必須"))
F35: =IF(A35="","",COUNTIFS($A$5:$A$304,A35,$D$5:$D$304,"必須"))
F36: =IF(A36="","",COUNTIFS($A$5:$A$304,A36,$D$5:$D$304,"必須"))
F37: =IF(A37="","",COUNTIFS($A$5:$A$304,A37,$D$5:$D$304,"必須"))
F38: =IF(A38="","",COUNTIFS($A$5:$A$304,A38,$D$5:$D$304,"必須"))
F39: =IF(A39="","",COUNTIFS($A$5:$A$304,A39,$D$5:$D$304,"必須"))
F40: =IF(A40="","",COUNTIFS($A$5:$A$304,A40,$D$5:$D$304,"必須"))
...

Sheet 老師需求單
A1: 115 學年度 科任老師排課需求單
A2: 教師姓名：＿＿＿＿＿＿＿＿ 任教科目：＿＿＿＿＿＿＿＿
A3: 請在不想被排課的格子畫記：「○」＝希望不排 「●」＝必須不排（最多 3 格）
A5: 節次 | B5: 星期一 | C5: 星期二 | D5: 星期三 | E5: 星期四 | F5: 星期五
A6: 第1節 | D6: 綠色迪士尼
A7: 第2節
A8: 大下課
A9: 第3節
A10: 第4節
A11: 午餐・午休
A12: 第5節
A13: 第6節
A14: 第7節
A16: 其他特殊要求或說明：
A21: ※「必須」最多 3 格，若大家都填同一時段可能排不出來，還請見諒。填好請交回教學組，謝謝您！

Sheet 節數檢核
A1: 10. 節數檢核（自動計算，不用填）
A2: 依「科任配課」「本土語預排」自動計算。科任節數為 0 的班級，代表還沒填配課。
A3: 班級 | B3: 科任節數 | C3: 其中到專科教室 | D3: 本土語節數 | E3: 特教抽離節數
A4: 1年1班 | B4: =SUMIF(科任配課!$C$5:$C$304,A4,科任配課!$D$5:$D$304) | C4: =SUMIFS(科任配課!$F$5:$F$304,科任配課!$C$5:$C$304,A4,科任配課!$E$5:$E$304,"<>原班教室") | D4: =COUNTIF(本土語預排!$A$5:$A$154,A4) | E4: =COUNTIF(特教抽離!$B$5:$B$124,A4)
A5: 1年2班 | B5: =SUMIF(科任配課!$C$5:$C$304,A5,科任配課!$D$5:$D$304) | C5: =SUMIFS(科任配課!$F$5:$F$304,科任配課!$C$5:$C$304,A5,科任配課!$E$5:$E$304,"<>原班教室") | D5: =COUNTIF(本土語預排!$A$5:$A$154,A5) | E5: =COUNTIF(特教抽離!$B$5:$B$124,A5)
A6: 1年3班 | B6: =SUMIF(科任配課!$C$5:$C$304,A6,科任配課!$D$5:$D$304) | C6: =SUMIFS(科任配課!$F$5:$F$304,科任配課!$C$5:$C$304,A6,科任配課!$E$5:$E$304,"<>原班教室") | D6: =COUNTIF(本土語預排!$A$5:$A$154,A6) | E6: =COUNTIF(特教抽離!$B$5:$B$124,A6)
A7: 1年4班 | B7: =SUMIF(科任配課!$C$5:$C$304,A7,科任配課!$D$5:$D$304) | C7: =SUMIFS(科任配課!$F$5:$F$304,科任配課!$C$5:$C$304,A7,科任配課!$E$5:$E$304,"<>原班教室") | D7: =COUNTIF(本土語預排!$A$5:$A$154,A7) | E7: =COUNTIF(特教抽離!$B$5:$B$124,A7)
A8: 1年5班 | B8: =SUMIF(科任配課!$C$5:$C$304,A8,科任配課!$D$5:$D$304) | C8: =SUMIFS(科任配課!$F$5:$F$304,科任配課!$C$5:$C$304,A8,科任配課!$E$5:$E$304,"<>原班教室") | D8: =COUNTIF(本土語預排!$A$5:$A$154,A8) | E8: =COUNTIF(特教抽離!$B$5:$B$124,A8)
A9: 1年6班 | B9: =SUMIF(科任配課!$C$5:$C$304,A9,科任配課!$D$5:$D$304) | C9: =SUMIFS(科任配課!$F$5:$F$304,科任配課!$C$5:$C$304,A9,科任配課!$E$5:$E$304,"<>原班教室") | D9: =COUNTIF(本土語預排!$A$5:$A$154,A9) | E9: =COUNTIF(特教抽離!$B$5:$B$124,A9)
A10: 1年7班 | B10: =SUMIF(科任配課!$C$5:$C$304,A10,科任配課!$D$5:$D$304) | C10: =SUMIFS(科任配課!$F$5:$F$304,科任配課!$C$5:$C$304,A10,科任配課!$E$5:$E$304,"<>原班教室") | D10: =COUNTIF(本土語預排!$A$5:$A$154,A10) | E10: =COUNTIF(特教抽離!$B$5:$B$124,A10)
A11: 1年8班 | B11: =SUMIF(科任配課!$C$5:$C$304,A11,科任配課!$D$5:$D$304) | C11: =SUMIFS(科任配課!$F$5:$F$304,科任配課!$C$5:$C$304,A11,科任配課!$E$5:$E$304,"<>原班教室") | D11: =COUNTIF(本土語預排!$A$5:$A$154,A11) | E11: =COUNTIF(特教抽離!$B$5:$B$124,A11)
A12: 1年9班 | B12: =SUMIF(科任配課!$C$5:$C$304,A12,科任配課!$D$5:$D$304) | C12: =SUMIFS(科任配課!$F$5:$F$304,科任配課!$C$5:$C$304,A12,科任配課!$E$5:$E$304,"<>原班教室") | D12: =COUNTIF(本土語預排!$A$5:$A$154,A12) | E12: =COUNTIF(特教抽離!$B$5:$B$124,A12)
A13: 1年10班 | B13: =SUMIF(科任配課!$C$5:$C$304,A13,科任配課!$D$5:$D$304) | C13: =SUMIFS(科任配課!$F$5:$F$304,科任配課!$C$5:$C$304,A13,科任配課!$E$5:$E$304,"<>原班教室") | D13: =COUNTIF(本土語預排!$A$5:$A$154,A13) | E13: =COUNTIF(特教抽離!$B$5:$B$124,A13)
A14: 1年11班 | B14: =SUMIF(科任配課!$C$5:$C$304,A14,科任配課!$D$5:$D$304) | C14: =SUMIFS(科任配課!$F$5:$F$304,科任配課!$C$5:$C$304,A14,科任配課!$E$5:$E$304,"<>原班教室") | D14: =COUNTIF(本土語預排!$A$5:$A$154,A14) | E14: =COUNTIF(特教抽離!$B$5:$B$124,A14)
A15: 1年12班 | B15: =SUMIF(科任配課!$C$5:$C$304,A15,科任配課!$D$5:$D$304) | C15: =SUMIFS(科任配課!$F$5:$F$304,科任配課!$C$5:$C$304,A15,科任配課!$E$5:$E$304,"<>原班教室") | D15: =COUNTIF(本土語預排!$A$5:$A$154,A15) | E15: =COUNTIF(特教抽離!$B$5:$B$124,A15)
... A74: 6年12班 | B74: =SUMIF(科任配課!$C$5:$C$304,A74,科任配課!$D$5:$D$304) | C74: =SUMIFS(科任配課!$F$5:$F$304,科任配課!$C$5:$C$304,A74,科任配課!$E$5:$E$304,"<>原班教室") | D74: =COUNTIF(本土語預排!$A$5:$A$154,A74) | E74: =COUNTIF(特教抽離!$B$5:$B$124,A74)
A75: 合計 | B75: =SUM(B4:B74) | C75: =SUM(C4:C74) | D75: =SUM(D4:D74) | E75: =SUM(E4:E74)

Sheet 選項
A1: 科目 | B1: 班級 | C1: 星期 | D1: 節次 | E1: 語別 | F1: 程度 | G1: 層級 | H1: 重要度 | I1: 啟用 | J1: 地點 | K1: 特教類型 | L1: 時段 | M1: 積木
A2: 英語 | B2: 1年1班 | C2: 一 | D2: 1 | E2: 閩南語 | F2: 必須 | G2: 0 法規 | H2: 高 | I2: 是 | J2: 原班教室 | K2: 資源班抽離 | L2: 1 | M2: 職務不排時段
A3: 自然 | B3: 1年2班 | C3: 二 | D3: 2 | E3: 客語 | F3: 希望 | G3: 1 鎖定 | H3: 中 | I3: 否 | J3: 自然教室 | K3: 集中式特教班 | L3: 2 | M3: 鎖定時段
A4: 社會 | B4: 1年3班 | C4: 三 | D4: 3 | E4: 族語 | G4: 2 必須 | H4: 低 | J4: 音樂教室 | L4: 3 | M4: 科目不排時段
A5: 健康 | B5: 1年4班 | C5: 四 | D5: 4 | E5: 新住民語 | G5: 3 盡量 | H5: — | J5: 電腦教室 | L5: 4 | M5: 老師不排時段
A6: 體育 | B6: 1年5班 | C6: 五 | D6: 5 | E6: 臺灣手語 | J6: 操場／體育館 | L6: 5 | M6: 每日節數上限
A7: 音樂 | B7: 1年6班 | D7: 6 | J7: 其他專科教室 | L7: 6 | M7: 連堂
A8: 美勞 | B8: 1年7班 | D8: 7 | L8: 7 | M8: 教室容量
A9: 資訊 | B9: 1年8班 | L9: 上午 | M9: 跑班距離
A10: 表演藝術 | B10: 1年9班 | L10: 下午 | M10: 其他
A11: 綜合 | B11: 1年10班 | L11: 整天 | M11: 同科分散
A12: 彈性 | B12: 1年11班 | M12: 間隔天數
A13: 其他 | B13: 1年12班
B14: 2年1班
B15: 2年2班
B16: 2年3班
B17: 2年4班
B18: 2年5班
B19: 2年6班
B20: 2年7班
B21: 2年8班
B22: 2年9班
B23: 2年10班
B24: 2年11班
B25: 3年1班
... B72: 6年12班
